<mujoco model="3dof_robot_arm">
    <compiler angle="radian" coordinate="local"/>
    <option gravity="0 0 -9.81" integrator="RK4" timestep="0.01"/>

    <worldbody>
            <light diffuse=".5 .5 .5" pos="0 0 3" dir="0 0 -1"/>
        <geom name="floor" pos="0 0 -0.1" size="1 1 0.1" type="plane" rgba="0.8 0.9 0.8 1"/>
         
        <!-- Base of the robot arm -->
        <body name="base" pos="0 0 0">
            <!-- Joint 1: Base rotation -->
            <joint name="joint1" type="hinge" axis="0 0 1" limited="true" range="-180 180"/>
            <!-- Link 1 -->
            <geom name="link1_geom" type="capsule" fromto="0 0 0 0 0 0.5" size="0.05" mass="1"/>
            <!-- Link 2 -->
            <body name="link2" pos="0 0 0.5">
                <!-- Joint 2: Shoulder pitch (up/down) -->
                <joint name="joint2" type="hinge" axis="0 1 0" limited="true" range="-90 90"/>
                <geom name="link2_geom" type="capsule" fromto="0 0 0 0 0 0.5" size="0.05" mass="0.8"/>
                <!-- Link 3 -->
                <body name="link3" pos="0 0 0.5">
                    <!-- Joint 3: Elbow pitch (up/down) -->
                    <joint name="joint3" type="hinge" axis="0 1 0" limited="true" range="-90 90"/>
                    <geom name="link3_geom" type="capsule" fromto="0 0 0 0 0 0.5" size="0.05" mass="0.6"/>
                    <!-- End-effector -->
                    <body name="end_effector" pos="0 0 0.5">
                        <geom type="sphere" size="0.05" rgba="1 0 0 1" mass="0.2"/>
                        <site name="end_eff" pos="0 0 0" size="0.01" rgba="1 0 0 1"/>
                    </body>
                </body>
            </body>
        </body>
<body name="target" pos="0.3 0.3 1">
            <geom name="target" type="sphere" size="0.02" rgba="0 0 1 0.5"/>
        </body>
    </worldbody>

    <actuator>
        <position joint="joint1" ctrlrange="-1.57 1.57" kp="7" kv="0.4" ctrllimited="true" gear="2"/>
        <position joint="joint2" ctrlrange="-1.57 1.57" ctrllimited="true" />
        <position joint="joint3" ctrlrange="-1.57 1.57" ctrllimited="true" />
    </actuator>
   <sensor>
    <jointpos name="joint1_pos" joint="joint1"/>
    <jointpos name="joint2_pos" joint="joint2"/>
    <jointpos name="joint3_pos" joint="joint3"/>
    <framepos name="end_effector_pos" objtype="body" objname="end_effector"/>
</sensor> 
</mujoco>