<mujoco model="two_joint_arm">
    <compiler angle="degree" inertiafromgeom="true"/>
    <option timestep="0.01" gravity="0 0 -9.81"/>
    <worldbody>
        <light diffuse=".5 .5 .5" pos="0 0 3" dir="0 0 -1"/>
        <geom name="floor" pos="0 0 -0.1" size="1 1 0.1" type="plane" rgba="0.8 0.9 0.8 1"/>
        <body name="base" pos="0 0 0">
            <geom name="base" type="cylinder" size="0.05 0.02" rgba="0.2 0.2 0.2 1"/>
            <body name="upper_arm" pos="0 0 0.02">
                <joint name="shoulder" type="hinge" axis="0 0 1" range="-90 90"/>
                <geom name="upper_arm" type="capsule" fromto="0 0 0 0.2 0 0" size="0.02" rgba="0.7 0.7 0 1"/>
                <body name="lower_arm" pos="0.2 0 0">
                    <joint name="elbow" type="hinge" axis="0 1 0" range="-90 90"/>
                    <geom name="lower_arm" type="capsule" fromto="0 0 0 0.2 0 0" size="0.02" rgba="0 0.7 0.7 1"/>
                    <site name="end_effector" pos="0.2 0 0" size="0.01" rgba="1 0 0 1"/>
                </body>
            </body>
        </body>
        <body name="target" pos="0.3 0 0.2">
            <geom name="target" type="sphere" size="0.02" rgba="1 0 0 0.5"/>
        </body>
    </worldbody>
    <actuator>
        <motor joint="shoulder" ctrlrange="-1 1" ctrllimited="true"/>
        <motor joint="elbow" ctrlrange="-1 1" ctrllimited="true"/>
    </actuator>
    <sensor>
        <touch name="touch_sensor" site="end_effector"/>
    </sensor>
</mujoco>
